

2022-09-14 12:29:53 | ERROR 	| ayaka.adapters.ayakabot_adapter:import_plugin:18 - plugins.chengyu 导入失败
Traceback (most recent call last):
  File "F:\code_project\robot\ayaka\ayakabot\ayaka\adapters\ayakabot_adapter\__init__.py", line 15, in import_plugin
    importlib.import_module(module_name)
  File "C:\Users\Administrator\AppData\Local\Programs\Python\Python38\lib\importlib\__init__.py", line 127, in import_module
    return _bootstrap._gcd_import(name[level:], package, level)
  File "<frozen importlib._bootstrap>", line 1014, in _gcd_import
  File "<frozen importlib._bootstrap>", line 991, in _find_and_load
  File "<frozen importlib._bootstrap>", line 975, in _find_and_load_unlocked
  File "<frozen importlib._bootstrap>", line 671, in _load_unlocked
  File "<frozen importlib._bootstrap_external>", line 783, in exec_module
  File "<frozen importlib._bootstrap>", line 219, in _call_with_frames_removed
  File "F:\code_project\robot\ayaka\ayakabot\plugins\chengyu\__init__.py", line 19, in <module>
    whole_bin = load("meaning")
  File "F:\code_project\robot\ayaka\ayakabot\plugins\chengyu\__init__.py", line 15, in load
    data: dict = json.load(open(path, "r", encoding="utf8"))
FileNotFoundError: [Errno 2] No such file or directory: './meaning.json'


2022-09-14 12:35:11 | ERROR 	| ayaka.adapters.ayakabot_adapter._import:import_plugin:13 - plugins.chengyu 导入失败
Traceback (most recent call last):
  File "F:\code_project\robot\ayaka\ayakabot\ayaka\adapters\ayakabot_adapter\_import.py", line 10, in import_plugin
    importlib.import_module(module_name)
  File "C:\Users\Administrator\AppData\Local\Programs\Python\Python38\lib\importlib\__init__.py", line 127, in import_module
    return _bootstrap._gcd_import(name[level:], package, level)
  File "<frozen importlib._bootstrap>", line 1014, in _gcd_import
  File "<frozen importlib._bootstrap>", line 991, in _find_and_load
  File "<frozen importlib._bootstrap>", line 975, in _find_and_load_unlocked
  File "<frozen importlib._bootstrap>", line 671, in _load_unlocked
  File "<frozen importlib._bootstrap_external>", line 783, in exec_module
  File "<frozen importlib._bootstrap>", line 219, in _call_with_frames_removed
  File "F:\code_project\robot\ayaka\ayakabot\plugins\chengyu\__init__.py", line 20, in <module>
    whole_bin = load("meaning")
  File "F:\code_project\robot\ayaka\ayakabot\plugins\chengyu\__init__.py", line 15, in load
    path = Path(__file__).parent.joinpath(f"./{name}.json")
NameError: name 'Path' is not defined


2022-09-14 12:39:21 | ERROR 	| ayaka.adapters.ayakabot_adapter._import:import_plugin:13 - plugins.chengyu 导入失败
Traceback (most recent call last):
  File "F:\code_project\robot\ayaka\ayakabot\ayaka\adapters\ayakabot_adapter\_import.py", line 10, in import_plugin
    importlib.import_module(module_name)
  File "C:\Users\Administrator\AppData\Local\Programs\Python\Python38\lib\importlib\__init__.py", line 127, in import_module
    return _bootstrap._gcd_import(name[level:], package, level)
  File "<frozen importlib._bootstrap>", line 1014, in _gcd_import
  File "<frozen importlib._bootstrap>", line 991, in _find_and_load
  File "<frozen importlib._bootstrap>", line 975, in _find_and_load_unlocked
  File "<frozen importlib._bootstrap>", line 671, in _load_unlocked
  File "<frozen importlib._bootstrap_external>", line 783, in exec_module
  File "<frozen importlib._bootstrap>", line 219, in _call_with_frames_removed
  File "F:\code_project\robot\ayaka\ayakabot\plugins\chengyu\__init__.py", line 15, in <module>
    whole_bin = load_json("meaning")
  File "F:\code_project\robot\ayaka\ayakabot\plugins\utils\file.py", line 7, in load_json
    data: dict = json.load(path.open("r", encoding="utf8"))
  File "C:\Users\Administrator\AppData\Local\Programs\Python\Python38\lib\pathlib.py", line 1218, in open
    return io.open(self, mode, buffering, encoding, errors, newline,
  File "C:\Users\Administrator\AppData\Local\Programs\Python\Python38\lib\pathlib.py", line 1074, in _opener
    return self._accessor.open(self, flags, mode)
FileNotFoundError: [Errno 2] No such file or directory: 'F:\\code_project\\robot\\ayaka\\ayakabot\\plugins\\utils\\meaning.json'


2022-09-14 12:40:12 | ERROR 	| ayaka.adapters.ayakabot_adapter._import:import_plugin:13 - plugins.chengyu 导入失败
Traceback (most recent call last):
  File "F:\code_project\robot\ayaka\ayakabot\ayaka\adapters\ayakabot_adapter\_import.py", line 10, in import_plugin
    importlib.import_module(module_name)
  File "C:\Users\Administrator\AppData\Local\Programs\Python\Python38\lib\importlib\__init__.py", line 127, in import_module
    return _bootstrap._gcd_import(name[level:], package, level)
  File "<frozen importlib._bootstrap>", line 1014, in _gcd_import
  File "<frozen importlib._bootstrap>", line 991, in _find_and_load
  File "<frozen importlib._bootstrap>", line 975, in _find_and_load_unlocked
  File "<frozen importlib._bootstrap>", line 671, in _load_unlocked
  File "<frozen importlib._bootstrap_external>", line 783, in exec_module
  File "<frozen importlib._bootstrap>", line 219, in _call_with_frames_removed
  File "F:\code_project\robot\ayaka\ayakabot\plugins\chengyu\__init__.py", line 9, in <module>
    from ..utils.file import load_json
ImportError: cannot import name 'load_json' from 'plugins.utils.file' (F:\code_project\robot\ayaka\ayakabot\plugins\utils\file.py)


2022-09-14 12:42:58 | ERROR 	| ayaka.adapters.ayakabot_adapter._import:import_plugin:13 - plugins.emoji 导入失败
Traceback (most recent call last):
  File "F:\code_project\robot\ayaka\ayakabot\ayaka\adapters\ayakabot_adapter\_import.py", line 10, in import_plugin
    importlib.import_module(module_name)
  File "C:\Users\Administrator\AppData\Local\Programs\Python\Python38\lib\importlib\__init__.py", line 127, in import_module
    return _bootstrap._gcd_import(name[level:], package, level)
  File "<frozen importlib._bootstrap>", line 1014, in _gcd_import
  File "<frozen importlib._bootstrap>", line 991, in _find_and_load
  File "<frozen importlib._bootstrap>", line 975, in _find_and_load_unlocked
  File "<frozen importlib._bootstrap>", line 671, in _load_unlocked
  File "<frozen importlib._bootstrap_external>", line 783, in exec_module
  File "<frozen importlib._bootstrap>", line 219, in _call_with_frames_removed
  File "F:\code_project\robot\ayaka\ayakabot\plugins\emoji\__init__.py", line 7, in <module>
    emojiBin = load_json("emoji")
  File "F:\code_project\robot\ayaka\ayakabot\plugins\utils\file.py", line 7, in load_local_json
    data: dict = json.load(path.open("r", encoding="utf8"))
  File "C:\Users\Administrator\AppData\Local\Programs\Python\Python38\lib\pathlib.py", line 1218, in open
    return io.open(self, mode, buffering, encoding, errors, newline,
  File "C:\Users\Administrator\AppData\Local\Programs\Python\Python38\lib\pathlib.py", line 1074, in _opener
    return self._accessor.open(self, flags, mode)
FileNotFoundError: [Errno 2] No such file or directory: 'F:\\code_project\\robot\\ayaka\\ayakabot\\plugins\\emoji\\emoji.json'


2022-09-14 13:14:27 | ERROR 	| ayaka.adapters.ayakabot_adapter._import:import_plugin:13 - plugins.chengyu 导入失败
Traceback (most recent call last):
  File "F:\code_project\robot\ayaka\ayakabot\ayaka\adapters\ayakabot_adapter\_import.py", line 10, in import_plugin
    importlib.import_module(module_name)
  File "C:\Users\Administrator\AppData\Local\Programs\Python\Python38\lib\importlib\__init__.py", line 127, in import_module
    return _bootstrap._gcd_import(name[level:], package, level)
  File "<frozen importlib._bootstrap>", line 1014, in _gcd_import
  File "<frozen importlib._bootstrap>", line 991, in _find_and_load
  File "<frozen importlib._bootstrap>", line 975, in _find_and_load_unlocked
  File "<frozen importlib._bootstrap>", line 671, in _load_unlocked
  File "<frozen importlib._bootstrap_external>", line 783, in exec_module
  File "<frozen importlib._bootstrap>", line 219, in _call_with_frames_removed
  File "F:\code_project\robot\ayaka\ayakabot\plugins\chengyu\__init__.py", line 10, in <module>
    from ..utils.file import load_local_json
ImportError: cannot import name 'load_local_json' from 'plugins.utils.file' (F:\code_project\robot\ayaka\ayakabot\plugins\utils\file.py)


2022-09-14 13:14:27 | ERROR 	| ayaka.adapters.ayakabot_adapter._import:import_plugin:13 - plugins.emoji 导入失败
Traceback (most recent call last):
  File "F:\code_project\robot\ayaka\ayakabot\ayaka\adapters\ayakabot_adapter\_import.py", line 10, in import_plugin
    importlib.import_module(module_name)
  File "C:\Users\Administrator\AppData\Local\Programs\Python\Python38\lib\importlib\__init__.py", line 127, in import_module
    return _bootstrap._gcd_import(name[level:], package, level)
  File "<frozen importlib._bootstrap>", line 1014, in _gcd_import
  File "<frozen importlib._bootstrap>", line 991, in _find_and_load
  File "<frozen importlib._bootstrap>", line 975, in _find_and_load_unlocked
  File "<frozen importlib._bootstrap>", line 671, in _load_unlocked
  File "<frozen importlib._bootstrap_external>", line 783, in exec_module
  File "<frozen importlib._bootstrap>", line 219, in _call_with_frames_removed
  File "F:\code_project\robot\ayaka\ayakabot\plugins\emoji\__init__.py", line 4, in <module>
    from ..utils.file import load_local_json
ImportError: cannot import name 'load_local_json' from 'plugins.utils.file' (F:\code_project\robot\ayaka\ayakabot\plugins\utils\file.py)


2022-09-14 13:15:16 | ERROR 	| ayaka.adapters.ayakabot_adapter._import:import_plugin:13 - plugins.emoji 导入失败
Traceback (most recent call last):
  File "F:\code_project\robot\ayaka\ayakabot\ayaka\adapters\ayakabot_adapter\_import.py", line 10, in import_plugin
    importlib.import_module(module_name)
  File "C:\Users\Administrator\AppData\Local\Programs\Python\Python38\lib\importlib\__init__.py", line 127, in import_module
    return _bootstrap._gcd_import(name[level:], package, level)
  File "<frozen importlib._bootstrap>", line 1014, in _gcd_import
  File "<frozen importlib._bootstrap>", line 991, in _find_and_load
  File "<frozen importlib._bootstrap>", line 975, in _find_and_load_unlocked
  File "<frozen importlib._bootstrap>", line 671, in _load_unlocked
  File "<frozen importlib._bootstrap_external>", line 783, in exec_module
  File "<frozen importlib._bootstrap>", line 219, in _call_with_frames_removed
  File "F:\code_project\robot\ayaka\ayakabot\plugins\emoji\__init__.py", line 4, in <module>
    from ..utils.file import load_local_json
ImportError: cannot import name 'load_local_json' from 'plugins.utils.file' (F:\code_project\robot\ayaka\ayakabot\plugins\utils\file.py)


2022-09-14 13:21:49 | ERROR 	| ayaka.adapters.ayakabot_adapter._import:import_plugin:13 - plugins.talk 导入失败
Traceback (most recent call last):
  File "F:\code_project\robot\ayaka\ayakabot\ayaka\adapters\ayakabot_adapter\_import.py", line 10, in import_plugin
    importlib.import_module(module_name)
  File "C:\Users\Administrator\AppData\Local\Programs\Python\Python38\lib\importlib\__init__.py", line 127, in import_module
    return _bootstrap._gcd_import(name[level:], package, level)
  File "<frozen importlib._bootstrap>", line 1014, in _gcd_import
  File "<frozen importlib._bootstrap>", line 991, in _find_and_load
  File "<frozen importlib._bootstrap>", line 975, in _find_and_load_unlocked
  File "<frozen importlib._bootstrap>", line 671, in _load_unlocked
  File "<frozen importlib._bootstrap_external>", line 783, in exec_module
  File "<frozen importlib._bootstrap>", line 219, in _call_with_frames_removed
  File "F:\code_project\robot\ayaka\ayakabot\plugins\talk\__init__.py", line 1, in <module>
    from .talk import app
  File "F:\code_project\robot\ayaka\ayakabot\plugins\talk\talk.py", line 5, in <module>
    corpus = Corpus(LocalPath(__file__).get_json_path("talk"))
TypeError: __init__() takes 1 positional argument but 2 were given


2022-09-14 13:28:34 | ERROR 	| ayaka.adapters.ayakabot_adapter._import:import_plugin:13 - plugins.mars 导入失败
Traceback (most recent call last):
  File "F:\code_project\robot\ayaka\ayakabot\ayaka\adapters\ayakabot_adapter\_import.py", line 10, in import_plugin
    importlib.import_module(module_name)
  File "C:\Users\Administrator\AppData\Local\Programs\Python\Python38\lib\importlib\__init__.py", line 127, in import_module
    return _bootstrap._gcd_import(name[level:], package, level)
  File "<frozen importlib._bootstrap>", line 1014, in _gcd_import
  File "<frozen importlib._bootstrap>", line 991, in _find_and_load
  File "<frozen importlib._bootstrap>", line 975, in _find_and_load_unlocked
  File "<frozen importlib._bootstrap>", line 671, in _load_unlocked
  File "<frozen importlib._bootstrap_external>", line 783, in exec_module
  File "<frozen importlib._bootstrap>", line 219, in _call_with_frames_removed
  File "F:\code_project\robot\ayaka\ayakabot\plugins\mars\__init__.py", line 7, in <module>
    charPYStr: str = mars_data['charPYStr']
KeyError: 'charPYStr'


2022-09-14 13:29:48 | ERROR 	| ayaka.adapters.ayakabot_adapter._import:import_plugin:13 - plugins.mars 导入失败
Traceback (most recent call last):
  File "F:\code_project\robot\ayaka\ayakabot\ayaka\adapters\ayakabot_adapter\_import.py", line 10, in import_plugin
    importlib.import_module(module_name)
  File "C:\Users\Administrator\AppData\Local\Programs\Python\Python38\lib\importlib\__init__.py", line 127, in import_module
    return _bootstrap._gcd_import(name[level:], package, level)
  File "<frozen importlib._bootstrap>", line 1014, in _gcd_import
  File "<frozen importlib._bootstrap>", line 991, in _find_and_load
  File "<frozen importlib._bootstrap>", line 975, in _find_and_load_unlocked
  File "<frozen importlib._bootstrap>", line 671, in _load_unlocked
  File "<frozen importlib._bootstrap_external>", line 783, in exec_module
  File "<frozen importlib._bootstrap>", line 219, in _call_with_frames_removed
  File "F:\code_project\robot\ayaka\ayakabot\plugins\mars\__init__.py", line 5, in <module>
    charPYStr: str = mars_data['charPYStr']
NameError: name 'mars_data' is not defined


2022-09-14 13:31:39 | ERROR 	| ayaka.adapters.ayakabot_adapter._import:import_plugin:13 - plugins.official 导入失败
Traceback (most recent call last):
  File "F:\code_project\robot\ayaka\ayakabot\ayaka\adapters\ayakabot_adapter\_import.py", line 10, in import_plugin
    importlib.import_module(module_name)
  File "C:\Users\Administrator\AppData\Local\Programs\Python\Python38\lib\importlib\__init__.py", line 127, in import_module
    return _bootstrap._gcd_import(name[level:], package, level)
  File "<frozen importlib._bootstrap>", line 1014, in _gcd_import
  File "<frozen importlib._bootstrap>", line 991, in _find_and_load
  File "<frozen importlib._bootstrap>", line 975, in _find_and_load_unlocked
  File "<frozen importlib._bootstrap>", line 671, in _load_unlocked
  File "<frozen importlib._bootstrap_external>", line 783, in exec_module
  File "<frozen importlib._bootstrap>", line 219, in _call_with_frames_removed
  File "F:\code_project\robot\ayaka\ayakabot\plugins\official\__init__.py", line 8, in <module>
    data:dict = LocalPath(__file__).load_json("official")
  File "F:\code_project\robot\ayaka\ayakabot\plugins\utils\file.py", line 14, in load_json
    return json.load(path.open("r", encoding="utf8"))
  File "C:\Users\Administrator\AppData\Local\Programs\Python\Python38\lib\pathlib.py", line 1218, in open
    return io.open(self, mode, buffering, encoding, errors, newline,
  File "C:\Users\Administrator\AppData\Local\Programs\Python\Python38\lib\pathlib.py", line 1074, in _opener
    return self._accessor.open(self, flags, mode)
FileNotFoundError: [Errno 2] No such file or directory: 'F:\\code_project\\robot\\ayaka\\ayakabot\\plugins\\official\\official.json'


2022-09-14 13:33:41 | ERROR 	| ayaka.adapters.ayakabot_adapter._import:import_plugin:13 - plugins.setu 导入失败
Traceback (most recent call last):
  File "F:\code_project\robot\ayaka\ayakabot\ayaka\adapters\ayakabot_adapter\_import.py", line 10, in import_plugin
    importlib.import_module(module_name)
  File "C:\Users\Administrator\AppData\Local\Programs\Python\Python38\lib\importlib\__init__.py", line 127, in import_module
    return _bootstrap._gcd_import(name[level:], package, level)
  File "<frozen importlib._bootstrap>", line 1014, in _gcd_import
  File "<frozen importlib._bootstrap>", line 991, in _find_and_load
  File "<frozen importlib._bootstrap>", line 975, in _find_and_load_unlocked
  File "<frozen importlib._bootstrap>", line 671, in _load_unlocked
  File "<frozen importlib._bootstrap_external>", line 783, in exec_module
  File "<frozen importlib._bootstrap>", line 219, in _call_with_frames_removed
  File "F:\code_project\robot\ayaka\ayakabot\plugins\setu\__init__.py", line 4, in <module>
    from .utils.spider import Spider
ModuleNotFoundError: No module named 'plugins.setu.utils'


2022-09-14 15:09:08 | ERROR 	| ayaka.adapter._bot:endpoint:52 - 连接中断
Traceback (most recent call last):
  File "F:\code_project\robot\ayaka\ayakabot\ayaka\adapter\_bot.py", line 41, in endpoint
    data = await ws.receive()
  File "F:\code_project\robot\ayaka\ayakabot\ayaka\adapter\onebot\websocket.py", line 23, in receive
    return await self.websocket.receive_text()
  File "C:\Users\Administrator\AppData\Local\Programs\Python\Python38\lib\site-packages\starlette\websockets.py", line 113, in receive_text
    self._raise_on_disconnect(message)
  File "C:\Users\Administrator\AppData\Local\Programs\Python\Python38\lib\site-packages\starlette\websockets.py", line 105, in _raise_on_disconnect
    raise WebSocketDisconnect(message["code"])
starlette.websockets.WebSocketDisconnect: 1006
